Workbook

Sheet Menu Master
A1: SKU | B1: Category | C1: Subcategory | D1: Item Name | E1: Variant | F1: Price (PHP) | G1: Notes
A2: F001 | B2: Food | C2: All Day Breakfast | D2: Hungarian Sausage | F2: 289
A3: F002 | B3: Food | C3: All Day Breakfast | D3: Pork Bacon | F3: 249
A4: F003 | B4: Food | C4: All Day Breakfast | D4: Homemade Corned Beef | F4: 269
A5: F004 | B5: Food | C5: All Day Breakfast | D5: Tomato Mozzarella Omelette | F5: 179
A6: F005 | B6: Food | C6: Rice Bowls | D6: Chicken Teriyaki | F6: 159
A7: F006 | B7: Food | C7: Rice Bowls | D7: Bicol Express | F7: 169
A8: F007 | B8: Food | C8: Rice Bowls | D8: Sweet and Sour Fish | F8: 174
A9: F008 | B9: Food | C9: Rice Bowls | D9: Garlic Pepper Beef | F9: 184
A10: F009 | B10: Food | C10: Pasta and Salad | D10: Creamy Garlic Shrimp Pasta | F10: 405
A11: F010 | B11: Food | C11: Pasta and Salad | D11: Chicken Alfredo Pasta | F11: 395
A12: F011 | B12: Food | C12: Pasta and Salad | D12: Spicy Shrimp Aglio Olio Pasta | F12: 395
A13: F012 | B13: Food | C13: Pasta and Salad | D13: Spaghetti and Meatballs | F13: 395
... A17: F016 | B17: Food | C17: Pasta and Salad | D17: Summer Salad | F17: 430
A18: F017 | B18: Food | C18: Burgers and Taco | D18: Quarter Pound Burger | E18: with homemade fries | F18: 269
A19: F018 | B19: Food | C19: Burgers and Taco | D19: Korean Chicken Sandwich | E19: with homemade fries | F19: 279
A20: F019 | B20: Food | C20: Burgers and Taco | D20: ChiliCon Carne Burger | E20: with homemade fries | F20: 319
A21: F020 | B21: Food | C21: Burgers and Taco | D21: Chicken Taco | F21: 249
A22: F021 | B22: Food | C22: Fries and Chips | D22: Homemade Fries | F22: 170
A23: F022 | B23: Food | C23: Fries and Chips | D23: Nachos | F23: 220
A24: F023 | B24: Food | C24: Meals | D24: Quarter Cut Fried Chicken | F24: 279
A25: F024 | B25: Food | C25: Meals | D25: Classic Garlic Parmesan Chicken | F25: 329
A26: F025 | B26: Food | C26: Meals | D26: Chicken Buffalo | F26: 329
A27: F026 | B27: Food | C27: Meals | D27: Pork Steak | F27: 320
A28: F027 | B28: Food | C28: Meals | D28: Old Fashioned Braised Beef | F28: 390
A29: F028 | B29: Food | C29: Meals | D29: Salisbury Steak | F29: 350
A30: F029 | B30: Food | C30: Meals | D30: Honey Garlic Salmon Steak | F30: 420
A31: F030 | B31: Food | C31: Meals | D31: Coconut Curry Salmon | F31: 420
A32: F031 | B32: Food | C32: Low and Slow Texas Style Smoked Barbecue | D32: Pork Belly | F32: 450
... A35: F034 | B35: Food | C35: Low and Slow Texas Style Smoked Barbecue | D35: Beef Brisket | F35: 550
A36: F035 | B36: Food | C36: Low and Slow Texas Style Smoked Barbecue | D36: Whole Slab Pork Ribs | F36: 1020 | G36: Menu image 1 shows 1,150; menu image 6/7 show 950 (most recent capture, May 2026) - using 950
A37: F036 | B37: Food | C37: For Sharing | D37: Pork Sinigang | F37: 450
A38: F037 | B38: Food | C38: For Sharing | D38: Crispy Pork Kare-Kare | F38: 570
A39: F038 | B39: Food | C39: For Sharing | D39: Beef Salpicao | F39: 460
A40: F039 | B40: Food | C40: For Sharing | D40: Gambas Al Ajillo | F40: 430
A41: F040 | B41: Food | C41: For Sharing | D41: Stir-Fry Vegetables | F41: 410
A42: F041 | B42: Food | C42: For Sharing | D42: Pancit Guisado | F42: 380
A43: F042 | B43: Food | C43: Cakes | D43: Classic Burnt Cheesecake | F43: 140
A44: F043 | B44: Food | C44: Cakes | D44: Red Velvet Cake | F44: 170
A45: F044 | B45: Food | C45: Cakes | D45: Chocolate Tablea Cake | F45: 170
...

Sheet Category Summary
A1: Category | B1: Subcategory | C1: Item Count | D1: Avg Price (PHP) | E1: Min Price (PHP) | F1: Max Price (PHP)
A2: Food | B2: All Day Breakfast | C2: =COUNTIFS('Menu Master'!$B$2:$B$102,A2,'Menu Master'!$C$2:$C$102,B2) | D2: =ROUND(AVERAGEIFS('Menu Master'!$F$2:$F$102,'Menu Master'!$B$2:$B$102,A2,'Menu Master'!$C$2:$C$102,B2),0) | E2: =_xlfn.MINIFS('Menu Master'!$F$2:$F$102,'Menu Master'!$B$2:$B$102,A2,'Menu Master'!$C$2:$C$102,B2) | F2: =_xlfn.MAXIFS('Menu Master'!$F$2:$F$102,'Menu Master'!$B$2:$B$102,A2,'Menu Master'!$C$2:$C$102,B2)
A3: Food | B3: Rice Bowls | C3: =COUNTIFS('Menu Master'!$B$2:$B$102,A3,'Menu Master'!$C$2:$C$102,B3) | D3: =ROUND(AVERAGEIFS('Menu Master'!$F$2:$F$102,'Menu Master'!$B$2:$B$102,A3,'Menu Master'!$C$2:$C$102,B3),0) | E3: =_xlfn.MINIFS('Menu Master'!$F$2:$F$102,'Menu Master'!$B$2:$B$102,A3,'Menu Master'!$C$2:$C$102,B3) | F3: =_xlfn.MAXIFS('Menu Master'!$F$2:$F$102,'Menu Master'!$B$2:$B$102,A3,'Menu Master'!$C$2:$C$102,B3)
A4: Food | B4: Pasta and Salad | C4: =COUNTIFS('Menu Master'!$B$2:$B$102,A4,'Menu Master'!$C$2:$C$102,B4) | D4: =ROUND(AVERAGEIFS('Menu Master'!$F$2:$F$102,'Menu Master'!$B$2:$B$102,A4,'Menu Master'!$C$2:$C$102,B4),0) | E4: =_xlfn.MINIFS('Menu Master'!$F$2:$F$102,'Menu Master'!$B$2:$B$102,A4,'Menu Master'!$C$2:$C$102,B4) | F4: =_xlfn.MAXIFS('Menu Master'!$F$2:$F$102,'Menu Master'!$B$2:$B$102,A4,'Menu Master'!$C$2:$C$102,B4)
A5: Food | B5: Burgers and Taco | C5: =COUNTIFS('Menu Master'!$B$2:$B$102,A5,'Menu Master'!$C$2:$C$102,B5) | D5: =ROUND(AVERAGEIFS('Menu Master'!$F$2:$F$102,'Menu Master'!$B$2:$B$102,A5,'Menu Master'!$C$2:$C$102,B5),0) | E5: =_xlfn.MINIFS('Menu Master'!$F$2:$F$102,'Menu Master'!$B$2:$B$102,A5,'Menu Master'!$C$2:$C$102,B5) | F5: =_xlfn.MAXIFS('Menu Master'!$F$2:$F$102,'Menu Master'!$B$2:$B$102,A5,'Menu Master'!$C$2:$C$102,B5)
A6: Food | B6: Fries and Chips | C6: =COUNTIFS('Menu Master'!$B$2:$B$102,A6,'Menu Master'!$C$2:$C$102,B6) | D6: =ROUND(AVERAGEIFS('Menu Master'!$F$2:$F$102,'Menu Master'!$B$2:$B$102,A6,'Menu Master'!$C$2:$C$102,B6),0) | E6: =_xlfn.MINIFS('Menu Master'!$F$2:$F$102,'Menu Master'!$B$2:$B$102,A6,'Menu Master'!$C$2:$C$102,B6) | F6: =_xlfn.MAXIFS('Menu Master'!$F$2:$F$102,'Menu Master'!$B$2:$B$102,A6,'Menu Master'!$C$2:$C$102,B6)
A7: Food | B7: Meals | C7: =COUNTIFS('Menu Master'!$B$2:$B$102,A7,'Menu Master'!$C$2:$C$102,B7) | D7: =ROUND(AVERAGEIFS('Menu Master'!$F$2:$F$102,'Menu Master'!$B$2:$B$102,A7,'Menu Master'!$C$2:$C$102,B7),0) | E7: =_xlfn.MINIFS('Menu Master'!$F$2:$F$102,'Menu Master'!$B$2:$B$102,A7,'Menu Master'!$C$2:$C$102,B7) | F7: =_xlfn.MAXIFS('Menu Master'!$F$2:$F$102,'Menu Master'!$B$2:$B$102,A7,'Menu Master'!$C$2:$C$102,B7)
A8: Food | B8: Low and Slow Texas Style Smoked Barbecue | C8: =COUNTIFS('Menu Master'!$B$2:$B$102,A8,'Menu Master'!$C$2:$C$102,B8) | D8: =ROUND(AVERAGEIFS('Menu Master'!$F$2:$F$102,'Menu Master'!$B$2:$B$102,A8,'Menu Master'!$C$2:$C$102,B8),0) | E8: =_xlfn.MINIFS('Menu Master'!$F$2:$F$102,'Menu Master'!$B$2:$B$102,A8,'Menu Master'!$C$2:$C$102,B8) | F8: =_xlfn.MAXIFS('Menu Master'!$F$2:$F$102,'Menu Master'!$B$2:$B$102,A8,'Menu Master'!$C$2:$C$102,B8)
A9: Food | B9: For Sharing | C9: =COUNTIFS('Menu Master'!$B$2:$B$102,A9,'Menu Master'!$C$2:$C$102,B9) | D9: =ROUND(AVERAGEIFS('Menu Master'!$F$2:$F$102,'Menu Master'!$B$2:$B$102,A9,'Menu Master'!$C$2:$C$102,B9),0) | E9: =_xlfn.MINIFS('Menu Master'!$F$2:$F$102,'Menu Master'!$B$2:$B$102,A9,'Menu Master'!$C$2:$C$102,B9) | F9: =_xlfn.MAXIFS('Menu Master'!$F$2:$F$102,'Menu Master'!$B$2:$B$102,A9,'Menu Master'!$C$2:$C$102,B9)
A10: Food | B10: Cakes | C10: =COUNTIFS('Menu Master'!$B$2:$B$102,A10,'Menu Master'!$C$2:$C$102,B10) | D10: =ROUND(AVERAGEIFS('Menu Master'!$F$2:$F$102,'Menu Master'!$B$2:$B$102,A10,'Menu Master'!$C$2:$C$102,B10),0) | E10: =_xlfn.MINIFS('Menu Master'!$F$2:$F$102,'Menu Master'!$B$2:$B$102,A10,'Menu Master'!$C$2:$C$102,B10) | F10: =_xlfn.MAXIFS('Menu Master'!$F$2:$F$102,'Menu Master'!$B$2:$B$102,A10,'Menu Master'!$C$2:$C$102,B10)
A11: Drinks | B11: Coffee | C11: =COUNTIFS('Menu Master'!$B$2:$B$102,A11,'Menu Master'!$C$2:$C$102,B11) | D11: =ROUND(AVERAGEIFS('Menu Master'!$F$2:$F$102,'Menu Master'!$B$2:$B$102,A11,'Menu Master'!$C$2:$C$102,B11),0) | E11: =_xlfn.MINIFS('Menu Master'!$F$2:$F$102,'Menu Master'!$B$2:$B$102,A11,'Menu Master'!$C$2:$C$102,B11) | F11: =_xlfn.MAXIFS('Menu Master'!$F$2:$F$102,'Menu Master'!$B$2:$B$102,A11,'Menu Master'!$C$2:$C$102,B11)
A12: Drinks | B12: Non-Coffee | C12: =COUNTIFS('Menu Master'!$B$2:$B$102,A12,'Menu Master'!$C$2:$C$102,B12) | D12: =ROUND(AVERAGEIFS('Menu Master'!$F$2:$F$102,'Menu Master'!$B$2:$B$102,A12,'Menu Master'!$C$2:$C$102,B12),0) | E12: =_xlfn.MINIFS('Menu Master'!$F$2:$F$102,'Menu Master'!$B$2:$B$102,A12,'Menu Master'!$C$2:$C$102,B12) | F12: =_xlfn.MAXIFS('Menu Master'!$F$2:$F$102,'Menu Master'!$B$2:$B$102,A12,'Menu Master'!$C$2:$C$102,B12)
A13: Drinks | B13: Frappes (espresso based) | C13: =COUNTIFS('Menu Master'!$B$2:$B$102,A13,'Menu Master'!$C$2:$C$102,B13) | D13: =ROUND(AVERAGEIFS('Menu Master'!$F$2:$F$102,'Menu Master'!$B$2:$B$102,A13,'Menu Master'!$C$2:$C$102,B13),0) | E13: =_xlfn.MINIFS('Menu Master'!$F$2:$F$102,'Menu Master'!$B$2:$B$102,A13,'Menu Master'!$C$2:$C$102,B13) | F13: =_xlfn.MAXIFS('Menu Master'!$F$2:$F$102,'Menu Master'!$B$2:$B$102,A13,'Menu Master'!$C$2:$C$102,B13)
... A18: Drinks | B18: Add-ons / Extras | C18: =COUNTIFS('Menu Master'!$B$2:$B$102,A18,'Menu Master'!$C$2:$C$102,B18) | D18: =ROUND(AVERAGEIFS('Menu Master'!$F$2:$F$102,'Menu Master'!$B$2:$B$102,A18,'Menu Master'!$C$2:$C$102,B18),0) | E18: =_xlfn.MINIFS('Menu Master'!$F$2:$F$102,'Menu Master'!$B$2:$B$102,A18,'Menu Master'!$C$2:$C$102,B18) | F18: =_xlfn.MAXIFS('Menu Master'!$F$2:$F$102,'Menu Master'!$B$2:$B$102,A18,'Menu Master'!$C$2:$C$102,B18)

Sheet Change Log
A1: Date Noted | B1: Item | C1: Old Price (PHP) | D1: New Price (PHP) | E1: Source / Notes
A2: 2026-05 capture | B2: Whole Slab Pork Ribs | C2: 1150 | D2: 950 | E2: Price reduced between menu photo sets (older photo showed 1,150; newer May 2026 Google Maps capture shows 950)
